Workbook

Sheet SALDOS
B1: TRANSPORTES FURLONG S.A.
B2: del 01/07/2026 al 31/07/2026 | F2: T.C. Reales al 31/7/26 | G2: 293.17575
C3: Deudor | D3: Acreedor | E3: saldo
B5: Activo
B7: 1110100330 FONDO FIJO BS. AS. | C7: =IF(E7>0,E7,0) -> 0 | D7: =IF(E7<0,E7*-1,0) -> 904.95437 | E7: =IFERROR(VLOOKUP(B7,$B$229:$C$286,2,FALSE),0) -> -904.95437
B8: 1110100340 FONDO FIJO SENASA | C8: =IF(E8>0,E8,0) -> 0 | D8: =IF(E8<0,E8*-1,0) -> 0 | E8: =IFERROR(VLOOKUP(B8,$B$229:$C$286,2,FALSE),0)
B9: 1110100420 BANCO FRANCES C/C | C9: =IF(E9>0,E9,0) -> 0 | D9: =IF(E9<0,E9*-1,0) -> 85668.934 | E9: =IFERROR(VLOOKUP(B9,$B$229:$C$286,2,FALSE),0) -> -85668.934
B10: 1110101050 FONDO FIJO ADELANTOS PDT | C10: =IF(E10>0,E10,0) -> 0 | D10: =IF(E10<0,E10*-1,0) -> 0 | E10: =IFERROR(VLOOKUP(B10,$B$229:$C$286,2,FALSE),0)
B11: 1120100100 FORD | C11: =IF(E11>0,E11,0) -> 0 | D11: =IF(E11<0,E11*-1,0) -> 2183.6622 | E11: =IFERROR(VLOOKUP(B11,$B$229:$C$286,2,FALSE),0) -> -2183.6622
B12: 1120100400 TRANSPORTES FURLONG S.A. AR | C12: =IF(E12>0,E12,0) -> 0 | D12: =IF(E12<0,E12*-1,0) -> 338665.61 | E12: =IFERROR(VLOOKUP(B12,$B$229:$C$286,2,FALSE),0) -> -338665.61
B13: 1120100700 RENAULT ARG. S.A. | C13: =IF(E13>0,E13,0) -> 0 | D13: =IF(E13<0,E13*-1,0) -> 0 | E13: =IFERROR(VLOOKUP(B13,$B$229:$C$286,2,FALSE),0)
B14: 1120101300 VOLKSWAGEN ARGENTINA S.A. | C14: =IF(E14>0,E14,0) -> 1039.3258 | D14: =IF(E14<0,E14*-1,0) -> 0 | E14: =IFERROR(VLOOKUP(B14,$B$229:$C$286,2,FALSE),0) -> 1039.3258
B15: 1120101600 FCA AUTOMOBILES ARGENTINA S.A. | C15: =IF(E15>0,E15,0) -> 0 | D15: =IF(E15<0,E15*-1,0) -> 0 | E15: =IFERROR(VLOOKUP(B15,$B$229:$C$286,2,FALSE),0)
B16: 1120131000 CNH ARGENTINA S.A. | C16: =IF(E16>0,E16,0) -> 0 | D16: =IF(E16<0,E16*-1,0) -> 371.40425 | E16: =IFERROR(VLOOKUP(B16,$B$229:$C$286,2,FALSE),0) -> -371.40425
B17: 1120138000 STELLANTIS AUTOMOVILES DE ARGENTINA S. A | C17: =IF(E17>0,E17,0) -> 0 | D17: =IF(E17<0,E17*-1,0) -> 655.71819 | E17: =IFERROR(VLOOKUP(B17,$B$229:$C$286,2,FALSE),0) -> -655.71819
B18: 1140300100 ANTICIPO A PDT | C18: =IF(E18>0,E18,0) -> 14061.316 | D18: =IF(E18<0,E18*-1,0) -> 0 | E18: =IFERROR(VLOOKUP(B18,$B$229:$C$286,2,FALSE),0) -> 14061.316
... B46: 1220400000 AMORT. ACUM. INSTALACIONES | C46: =IF(E46>0,E46,0) -> 0 | D46: =IF(E46<0,E46*-1,0) -> 0 | E46: =IFERROR(VLOOKUP(B46,$B$229:$C$286,2,FALSE),0)
B47: 1220600000 AMORT. ACUM. COMPUTADORAS | C47: =IF(E47>0,E47,0) -> 0 | D47: =IF(E47<0,E47*-1,0) -> 293.35549 | E47: =IFERROR(VLOOKUP(B47,$B$229:$C$286,2,FALSE),0) -> -293.35549 | G47: =SUM(E29:E48) -> -8477.1634
B48: 1220700000 AMORT. ACUM. RODADOS | C48: =IF(E48>0,E48,0) -> 0 | D48: =IF(E48<0,E48*-1,0) -> 8171.1751 | E48: =IFERROR(VLOOKUP(B48,$B$229:$C$286,2,FALSE),0) -> -8171.1751
E49: =SUM(E7:E48) -> -516470.14 | F49: =+E49-EESP!F33 -> -338665.61 | G49: =-F49+E12 -> 0
B50: Pasivo
A52: COTELCAM | B52: 2110100300 COTELCAM | C52: =IF(E52>0,E52,0) -> 0 | D52: =IF(E52<0,E52*-1,0) -> 0 | E52: =IFERROR(VLOOKUP(B52,$B$229:$C$286,2,FALSE),0)
B53: 2110102400 OSDE | C53: =IF(E53>0,E53,0) -> 0 | D53: =IF(E53<0,E53*-1,0) -> 0 | E53: =IFERROR(VLOOKUP(B53,$B$229:$C$286,2,FALSE),0)
A54: ESTUDIO CORTES | B54: 2110100900 ESTUDIO CORTES | C54: =IF(E54>0,E54,0) -> 0 | D54: =IF(E54<0,E54*-1,0) -> 0 | E54: =IFERROR(VLOOKUP(B54,$B$229:$C$286,2,FALSE),0)
A55: VENEZIA AUTOS SA | B55: 2110101500 VENEZIA AUTOS SA | C55: =IF(E55>0,E55,0) -> 0 | D55: =IF(E55<0,E55*-1,0) -> 0 | E55: =IFERROR(VLOOKUP(B55,$B$229:$C$286,2,FALSE),0)
A56: TRANSPORTES FURLONG ARG. S.A | B56: 2110101800 TRANSPORTES FURLONG ARG. S.A | C56: =IF(E56>0,E56,0) -> 0 | D56: =IF(E56<0,E56*-1,0) -> 0 | E56: =IFERROR(VLOOKUP(B56,$B$229:$C$286,2,FALSE),0)
A57: MERCOVIA S.A. | B57: 2110105400 MERCOVIA S.A. | C57: =IF(E57>0,E57,0) -> 202.40027 | D57: =IF(E57<0,E57*-1,0) | E57: =IFERROR(VLOOKUP(B57,$B$229:$C$286,2,FALSE),0) -> 202.40027
A58: OKINET SRL | B58: 2110106800 OKINET SRL | C58: =IF(E58>0,E58,0) -> 554.38087 | D58: =IF(E58<0,E58*-1,0) | E58: =IFERROR(VLOOKUP(B58,$B$229:$C$286,2,FALSE),0) -> 554.38087
A59: LA MERIDIONAL S.A. | B59: 2110108900 LA MERIDIONAL S.A. | C59: =IF(E59>0,E59,0) | D59: =IF(E59<0,E59*-1,0) | E59: =IFERROR(VLOOKUP(B59,$B$229:$C$286,2,FALSE),0)
A60: GIULI SERGIO ALBERTO | B60: 2110115100 GIULI SERGIO ALBERTO | C60: =IF(E60>0,E60,0) | D60: =IF(E60<0,E60*-1,0) | E60: =IFERROR(VLOOKUP(B60,$B$229:$C$286,2,FALSE),0)
A61: CARLOS ALEJANDRO DUMA | B61: 2110116700 CARLOS ALEJANDRO DUMA | C61: =IF(E61>0,E61,0) | D61: =IF(E61<0,E61*-1,0) | E61: =IFERROR(VLOOKUP(B61,$B$229:$C$286,2,FALSE),0)
A62: MANGGINI PABLO Y ULISES S.H | B62: 2110118000 MANGGINI PABLO Y ULISES S.H | C62: =IF(E62>0,E62,0) | D62: =IF(E62<0,E62*-1,0) | E62: =IFERROR(VLOOKUP(B62,$B$229:$C$286,2,FALSE),0)
A63: QBE SEGUROS LA BUENOS AIRES S.A. | B63: 2110120600 QBE SEGUROS LA BUENOS AIRES S.A. | C63: =IF(E63>0,E63,0) -> 76974.842 | D63: =IF(E63<0,E63*-1,0) | E63: =IFERROR(VLOOKUP(B63,$B$229:$C$286,2,FALSE),0) -> 76974.842
B64: 2110131700 LIBRERIA MAYA SA | C64: =IF(E64>0,E64,0) | D64: =IF(E64<0,E64*-1,0) | E64: =IFERROR(VLOOKUP(B64,$B$229:$C$286,2,FALSE),0)
A65: SERVI OESTE S.A | B65: 2110125800 SERVI OESTE S.A | C65: =IF(E65>0,E65,0) | D65: =IF(E65<0,E65*-1,0) | E65: =IFERROR(VLOOKUP(B65,$B$229:$C$286,2,FALSE),0)
A66: RODRIGO E. FONTAN | B66: 2110126900 RODRIGO E. FONTAN | C66: =IF(E66>0,E66,0) | D66: =IF(E66<0,E66*-1,0) | E66: =IFERROR(VLOOKUP(B66,$B$229:$C$286,2,FALSE),0)
B67: 2110132900 AURELIA S.A.C.I.F. | C67: =IF(E67>0,E67,0) | D67: =IF(E67<0,E67*-1,0) -> 27115.822 | E67: =IFERROR(VLOOKUP(B67,$B$229:$C$286,2,FALSE),0) -> -27115.822
A68: AB Fiduciaria S.A. | B68: 2110127300 AB Fiduciaria S.A. | C68: =IF(E68>0,E68,0) | D68: =IF(E68<0,E68*-1,0) | E68: =IFERROR(VLOOKUP(B68,$B$229:$C$286,2,FALSE),0)
A69: LAURA DI GIROLAMO | B69: 2110129600 LAURA DI GIROLAMO | C69: =IF(E69>0,E69,0) | D69: =IF(E69<0,E69*-1,0) | E69: =IFERROR(VLOOKUP(B69,$B$229:$C$286,2,FALSE),0)
A70: LUCIO JORGE ZEMBORAIN | B70: 2110130100 LUCIO JORGE ZEMBORAIN | C70: =IF(E70>0,E70,0) | D70: =IF(E70<0,E70*-1,0) | E70: =IFERROR(VLOOKUP(B70,$B$229:$C$286,2,FALSE),0)
...

Sheet EESP
A1: TRANSPORTES FURLONG S.A
A3: 31 de Julio de 2026
A5: Estado de Situación Patrimonial
F9: 46234 | L9: =+F9 -> 46234 | M9: 38717
B10: ACTIVO: | I10: PASIVO
C11: ACTIVO CORRIENTE | I11: PASIVO CORRIENTE
D12: Caja y bancos (Nota 4.a) | F12: =+Activo!F16 -> -86573.889 | J12: Deudas
D13: Creditos comerciales | F13: 0 | K13: Deudas impositivas
D14: Creditos Impositivos | F14: =+Activo!F34 -> 0 | K14: Deudas accionistas | L14: 0
D15: Inversiones temporarias (Nota 4.b) | F15: =+Activo!F23 -> -70990.504 | K15: Comerciales (Nota 4.e) | L15: =+Pasivo!E16 -> 297601.37
K16: Otras deudas (Nota 4.f) | L16: =+Pasivo!E22 -> 0
D17: Créditos por ventas (Nota 4.c) | F17: =+Activo!F26 -> -2171.4588 | K17: Remuneraciones y cs.sociales (Nota 4.f) | L17: =+Pasivo!E28 -> -129433.41
K18: Cargas fiscales (Nota 4.h) | L18: =+Pasivo!E35 -> 645.62953
D19: Otros activos | F19: 0 | K19: Anticipos de clientes | L19: 0
K20: Dividendos a pagar | L20: 0
D22: Otros Creditos (Nota 4.d) | F22: =+Activo!F57 -> -9591.5153 | J22: Total deudas | L22: =SUM(L13:L21) -> 168813.58
J23: Previsones | L23: 0
C24: Total del Activo corriente | F24: =SUM(F12:G22) -> -169327.37 | I24: Total del Pasivo Corriente | L24: =+L22+L23 -> 168813.58
I25: Total del Pasivo | L25: =+L24 -> 168813.58
C28: ACTIVO NO CORRIENTE
D29: Bienes de uso (Anexo l ) | F29: =+'Anexo I'!K18 -> -8477.1634 | I29: PATRIMONIO NETO (Según estado respec.) | L29: =+EEPN!J18 -> -346618.12
C31: Total del Activo no corriente | F31: =SUM(F29:F30) -> -8477.1634 | L31: =+L29 -> -346618.12
C33: Total del Activo | F33: =+F24+F31 -> -177804.53 | I33: Total del Pasivo y Patrimonio Neto | L33: =+L25+L31+0.01 -> -177804.53

Sheet EERR
A1: TRANSPORTES FURLONG S.A
A3: =+EESP!A3 -> 31 de Julio de 2026
A5: Estado de Resultados
C9: =+EESP!F9 -> 46234 | D9: =+EESP!G9 -> 0
A12: Ingresos por servicios prestados | C12: =+SALDOS!D119-SALDOS!C119
A15: Gastos de comercialización (Anexo II) | C15: =+'Anexo II'!E108 -> 317420.98
A16: Gastos de administración (Anexo II) | C16: =+'Anexo II'!D108 -> 28817.34
A17: Gastos de financieros (Anexo II) | C17: =+'Anexo II'!F108 -> 5921.83
A19: Subtotal | C19: =+C12+C13-C15-C16-C17 -> -352160.15
A20: Resultado venta bienes de uso | C20: =+SALDOS!D125
A21: Otros Ingresos | C21: =+SALDOS!D121+SALDOS!D124+SALDOS!D205+SALDOS!D122 -> 2310.25
A22: Diferencia de cambio | C22: =+SALDOS!D222 -> 3231.7768
A23: Diferencia de cotización | C23: =-SALDOS!C222
A24: Intereses | C24: =+SALDOS!D126
A25: Ganancia antes de impuesto | C25: =+C19+C20+C22+C21+C24+C23 -> -346618.12
A26: Impuesto a las Ganancias
A28: Ganancia del ejercicio | C28: =+C25-C26 -> -346618.12

Sheet EEPN
A1: =+EESP!A1 -> TRANSPORTES FURLONG S.A
A2: =+EESP!A3 -> 31 de Julio de 2026 | B2: =+EESP!A3 -> 31 de Julio de 2026
A3: Estado de Evolución del Patrimonio Neto
J5: =+EESP!F9 -> 46234 | K5: =+EESP!G9 -> 0
B6: CONCEPTO | C6: Aportes de los propietarios | F6: Ganancias | G6: Reservadas | I6: Resultados | J6: Total del | K6: Total del
C7: Capital | D7: Ajuste | E7: Total de | F7: Reserva | G7: Otras | H7: Aportes | I7: no | J7: patrimonio | K7: patrimonio
D8: de Capital | E8: Capital | F8: legal | G8: reservas | H8: Irrevocables | I8: asignados | J8: neto | K8: neto
C9: $ | D9: $ | E9: $ | F9: $ | G9: $ | H9: $ | I9: $ | J9: $ | K9: $
B11: Saldos al inicio del ejercicio | C11: 0 | D11: 0 | E11: =+C11+D11 -> 0 | F11: 0 | G11: 0 | H11: 0 | I11: =-SALDOS!E116 | J11: =+E11+F11+G11+I11 -> 0
C13: =SUM(C11:C11) -> 0 | D13: =SUM(D11:D11) -> 0 | E13: =SUM(E11:E11) -> 0 | F13: =SUM(F11:F11) -> 0 | G13: =SUM(G11:G11) -> 0 | H13: =SUM(H11:H11) -> 0 | I13: =+I12+I11 -> 0 | J13: =+J12+J11 -> 0 | K13: =SUM(K11:K11) -> 0
B15: Reasignación Casa Matriz | I15: 0 | J15: =+E15+F15+G15+I15 -> 0
B16: Ganancia (Pérdida) del ejercicio | I16: =+EERR!C28 -> -346618.12 | J16: =+I16 -> -346618.12
B18: Total al 31/7/26 | C18: =+C13 -> 0 | D18: =+D13 -> 0 | E18: =+E13 -> 0 | F18: =+F13 -> 0 | G18: =+G13 -> 0 | H18: =+H13 -> 0 | I18: =+I13+I16+I14+I15 -> -346618.12 | J18: =+J13+J16+J15 -> -346618.12 | K18: =+K13+K16 -> 0
B19: Total al 31.12.05 | E19: =+C19+D19 -> 0 | G19: 0 | I19: 0 | J19: =+E19 -> 0 | K19: =+G19 -> 0
B21: Las notas y anexos adjuntos forman parte integrante de los estados contables
B22: Informe profesional por separado

Sheet Activo
B1: NOTA 4: | E1: COMPOSICION DE LOS RUBROS
B3: =+EESP!A3 -> 31 de Julio de 2026
F5: =+EESP!F9 -> 46234 | H5: 38717
B6: ACTIVO
B7: Activo Corriente
B8: a. | C8: Caja y bancos
D9: - Caja
D10: - Fondo Fijo SENASA | F10: =+SALDOS!D8+SALDOS!C8 -> 0
D11: - Fondo Fijo | F11: =SALDOS!C7-SALDOS!D7 -> -904.95437
D12: - Banco Francés c/c | F12: =SALDOS!C9-SALDOS!D9 -> -85668.934
D13: - Fondo fijo Adelantos PDT | F13: =+SALDOS!D10+SALDOS!C10 -> 0
D14: - Adelanto casa matriz
D15: - Valores a depositar
F16: =SUM(F9:F15) -> -86573.889
B18: b. | C18: Inversiones temporarias
D19: - Fondo Común de inversión | F19: =-SALDOS!D28+SALDOS!C28 -> -70990.504
D20: - Plazo Fijo
D21: - Plazo Fijo | F21: =-SALDOS!D40 -> 0
D22: - Intereses a dev Plazo Fijo | F22: =+SALDOS!C41 -> 0
F23: =SUM(F19:F22) -> -70990.504
B24: c. | C24: Creditos por Ventas
D25: - Deudores por ventas | F25: =+SALDOS!C14+SALDOS!C16+SALDOS!C17-SALDOS!D11-SALDOS!D14-SALDOS!D16-SALDOS!D15-SALDOS!D17 -> -2171.4588
F26: =SUM(F25:F25) -> -2171.4588
C28: Creditos impositivos
D29: - Retencion de Gcias. | F29: 0
D30: - Retenc. Suss | F30: 0
D31: - Reten. Ingresos Brutos | F31: 0
D32: - Retenciones y Percepciones IVA | F32: 0
D33: - Crédito ley 25413 | F33: 0
F34: =SUM(F29:F33) -> 0
B36: d. | C36: Otros créditos
D37: - Transportes Furlong Uruguay
D38: - Transportes Furlong Cordoba
D39: - Adelanto de gastos
D40: - Adelantos Tomás Furlong
D41: - Adelantos PDT | F41: =+SALDOS!C18-SALDOS!D18 -> 14061.316
D42: - Adelanto honorarios CF
D43: - Anticipo de vacaciones | F43: =+SALDOS!E22 -> 0
D44: - Prestamo Vera | F44: =+SALDOS!C24-SALDOS!D24 -> 0
D45: - Adelanto SAC
...

Sheet Pasivo
E1: =+Activo!F5 -> 46234 | G1: 31.03.04 | K1: 31.03.03 | L1: =+EESP!G9 -> 0
A2: Pasivo
A3: Pasivo Corriente
A4: e. | B4: Deudas comerciales
C5: - Provisión Multas a pagar
C6: - Provisión fletes esporádicos
C7: - Previsiones
C8: - Proveedores | E8: =-SALDOS!E57-SALDOS!E58-SALDOS!E63-SALDOS!E67-SALDOS!E78-SALDOS!E97-SALDOS!E102-SALDOS!E104-SALDOS!E108-0.01 -> -13948.418
C9: - Adelanto casa matriz | E9: =-SALDOS!E12-SALDOS!E90 -> 311549.78
C10: - Adelanto de clientes
C11: - Siniestros a pagar
C12: - Prestamos a pagar
C13: - Prestamo Amx - Claro
C14: - Rodados a patentar
C15: - Cheques emitidos
E16: =SUM(E5:E15) -> 297601.37
A18: f. | B18: Otras Deudas
C19: - Acuerdos CNRT a pagar | E19: =-SALDOS!C91
C20: - Prestamo Carlos Furlong | E20: =-SALDOS!C19 -> 0
C21: - Prestamo Lorena Alves
E22: =+SUM(E19:E21) -> 0
A25: f. | B25: Remuneraciones y cs. Sociales
C26: - SUSS a pagar | E26: =-SALDOS!E83 -> -20201.506
C27: - Sueldos a pagar | E27: =-SALDOS!E82 -> -109231.91
E28: =SUM(E26:E27) -> -129433.41
A31: h. | B31: Cargas Fiscales
C32: - Plan Mis Facilidades | E32: =-SALDOS!E85 -> -286.43025
C33: - Interes a devengar | E33: =-SALDOS!E86 -> 55.880723
C34: - SICORE a pagar | E34: =-SALDOS!E84 -> 876.17906 | G34: 70 | K34: 0
E35: =SUM(E32:E34) -> 645.62953 | G35: =SUM(G34:G34) -> 70 | K35: =SUM(#REF!) -> #REF!

Sheet Anexo I
A1: B I E N E S D E U S O
A2: =+EESP!A3 -> 31 de Julio de 2026
B5: VALOR DE ORIGEN | F5: DEPRECIACIONES
B6: VALORES AL | E6: VALORES AL | F6: ACUMULADAS | H6: DEL EJERCICIO | J6: ACUMULADAS | K6: NETO
A7: CONCEPTO | B7: COMIENZO DEL | C7: AUMENTOS | D7: DISMINUCIONES | E7: CIERRE DEL | F7: AL INICIO DEL | G7: BAJAS | H7: ALICUOTA | I7: MONTO | J7: AL CIERRE DEL | K7: RESULTANTE
B8: EJERCICIO | E8: EJERCICIO | F8: EJERCICIO | J8: EJERCICIO | K8: =+EESP!F9 -> 46234
B9: $ | C9: $ | D9: $ | E9: $ | F9: $ | G9: $ | I9: $ | J9: $ | K9: $
A11: Software | B11: 0 | C11: 0 | E11: 0 | F11: 0 | H11: 0.2 | I11: 0 | J11: =+I11 -> 0 | K11: =+E11-J11 -> 0
A12: Hardware | B12: 0 | C12: 0 | E12: 0 | F12: 0 | H12: 0.2 | I12: 0 | J12: =+I12 -> 0 | K12: =+E12-J12 -> 0
A13: Computadoras | B13: 0 | C13: 0 | E13: 0 | F13: 0 | H13: 0.2 | I13: =-SALDOS!E47 -> 293.35549 | J13: =+I13 -> 293.35549 | K13: =+E13-J13 -> -293.35549
A14: Equipos | B14: 0 | C14: 0 | D14: 0 | E14: 0 | F14: 0 | H14: 0.2 | I14: 0 | J14: =+I14 -> 0 | K14: =+E14-J14 -> 0
A15: Muebles y Utiles | B15: 0 | C15: 0 | E15: 0 | F15: 0 | H15: 0.1 | I15: =-SALDOS!E42 -> 12.632834 | J15: =+I15 -> 12.632834 | K15: =+E15-J15 -> -12.632834
A16: Instalaciones | B16: 0 | C16: 0 | E16: 0 | F16: 0 | H16: 0.1 | I16: 0 | J16: =+I16 -> 0 | K16: =+E16-J16 -> 0
A17: Rodados | B17: 0 | C17: 0 | D17: =+#REF! -> #REF! | E17: 0 | F17: 0 | G17: 0 | H17: 0.2 | I17: =-SALDOS!E48 -> 8171.1751 | J17: =+I17 -> 8171.1751 | K17: =+E17-J17 -> -8171.1751
A18: =+EEPN!B18 -> Total al 31/7/26 | B18: =SUM(B11:B17) -> 0 | C18: =SUM(C11:C17) -> 0 | D18: =SUM(D11:D17) -> #REF! | E18: =SUM(E11:E17) -> 0 | F18: =SUM(F11:F17) -> 0 | G18: =SUM(G17) -> 0 | I18: =SUM(I11:I17) -> 8477.1634 | J18: =SUM(J11:J17) -> 8477.1634 | K18: =SUM(K11:K17) -> -8477.1634
A21: Las notas y anexos adjuntos forman parte integrante de los estados contables
A22: Informe profesional por separado

Sheet Anexo II
G1: ANEXO II
A3: Información Requerida por el Art. 64 Inc. b) de la Ley 19.550 | F3: Anexo II
A4: =+Activo!B3 -> 31 de Julio de 2026
C6: TOTALES | D6: GASTOS | E6: GASTOS | F6: GASTOS | G6: TOTALES
B7: CONCEPTOS | C7: AL | D7: DE | E7: DE | G7: AL | J7: GASTOS ADM CTRAL | K7: GASTOS PACHECO | L7: GASTOS CORDOBA | M7: COSTOS TRANSPORTES | N7: TOTAL | O7: PAGOS ANTIC | P7: TRANF CASA MATRIZ | Q7: TOTAL EGRESO
C8: =+EESP!F9 -> 46234 | D8: ADMINISTRACION | E8: COMERCIALIZACION | F8: FINANCIEROS | G8: 31.03.02
B9: Acuerdo SECLO | C9: =SUM(D9:F9) -> 0 | D9: 0 | E9: =+SALDOS!C151 | F9: 0
B10: Adelanto Viaje | C10: =SUM(D10:F10) -> 0 | D10: 0 | E10: =+SALDOS!C204 | F10: 0
B11: Alquiler de autos | C11: =SUM(D11:F11) -> 0 | D11: 0 | E11: =+SALDOS!C187 | F11: 0
B12: Alquiler cochera | C12: =SUM(D12:F12) -> 0 | D12: 0 | E12: =+SALDOS!C194 | F12: 0
B13: Alquiler dpto. | C13: =SUM(D13:F13) -> 0 | D13: 0 | E13: =+SALDOS!C192 | F13: 0
B14: Alquiler fotocopiadora | C14: =SUM(D14:F14) -> 1633.99 | D14: =+SALDOS!C150 -> 1633.99 | E14: 0 | F14: 0
B15: Alquiler Oficina Móvil | C15: =SUM(D15:F15) -> 0 | D15: =+SALDOS!C153 | E15: 0 | F15: 0
B16: Amortizaciones | C16: =SUM(D16:F16) -> 8674.63 | D16: =+SALDOS!C148 -> 8674.63 | E16: 0 | F16: 0
B17: Publicidad | C17: =SUM(D17:F17) -> 0 | D17: 0 | E17: =+SALDOS!C200 | F17: 0
B18: Almuerzos | C18: =SUM(D18:F18) -> 0 | D18: 0 | E18: 0 | F18: 0
B19: Autónomos Directores | C19: =SUM(D19:F19) -> 251.68 | D19: =+SALDOS!C180 -> 251.68 | E19: 0 | F19: 0
B20: Agua | C20: =SUM(D20:F20) -> 0 | D20: =+SALDOS!C149 | E20: 0 | F20: 0
B21: Ajuste saldo proveedores | C21: =SUM(D21:F21) -> 0 | D21: 0 | E21: =+SALDOS!C219 | F21: 0
B22: Bs Personales Acc. Y Participacion | C22: =SUM(D22:F22) -> 0 | D22: =++SALDOS!C186 | E22: 0 | F22: 0
B23: Sueldos | C23: =SUM(D23:F23) -> 0 | D23: 0 | E23: 0 | F23: 0
B24: Comisiones | C24: =SUM(D24:F24) -> 0 | D24: 0 | E24: =+SALDOS!C193 | F24: 0
B25: Gastos varios clientes | C25: =SUM(D25:F25) -> 0 | D25: 0 | E25: 0 | F25: 0
B26: Verificación Técnica Vehicular | C26: =SUM(D26:F26) -> 275.24 | D26: 0 | E26: =+SALDOS!C203+SALDOS!C176 -> 275.24 | F26: 0
B27: Amortizaciones | C27: =SUM(D27:F27) -> 0 | D27: 0 | E27: 0 | F27: 0
B28: Accidentes | C28: =SUM(D28:F28) -> 0 | D28: 0 | E28: =+SALDOS!C188 | F28: 0 | I28: OBRA SOCIAL | J28: 3400.5126 | K28: 5282.0813 | L28: 3714.6061 | P28: 4372 | R28: ACA ES LA FACTURA QUE SE VA A PAGAR EL MES PRÓXIMO SE INCLUYE EN CARGAS SOCIALES (EN EL BALANCE)
B29: Cargas Sociales | C29: =SUM(D29:F29) -> 30470.95 | D29: 0 | E29: =+SALDOS!C132 -> 30470.95 | F29: 0 | I29: C SOCIALES | J29: 7385.6622 | K29: 30178.815 | L29: 9981.5423 | R29: CORRESPONDE AL MES DE MAYO / SE PAGA EN JUNIO
B30: Telefonos | C30: =SUM(D30:F30) -> 0 | D30: 0 | E30: 0 | F30: 0
B31: Librería | C31: =SUM(D31:F31) -> 0 | D31: 0 | E31: 0 | F31: 0
B32: Leasing | C32: =SUM(D32:F32) -> 0 | D32: 0 | E32: =+SALDOS!C213 | F32: 0 | I32: ALQUILER | L32: =+E32 -> 0
B33: Viaticos | C33: =SUM(D33:F33) -> 0 | D33: 0 | E33: 0 | F33: 0
B34: Repuestos y reparaciones | C34: =SUM(D34:F34) -> 0 | D34: =+SALDOS!C181 | E34: 0 | F34: 0
B35: Catering | C35: =SUM(D35:F35) -> 0 | D35: 0 | E35: 0 | F35: 0 | I35: COMIDA | J35: 474 | K35: 528
B36: CNRT | C36: =SUM(D36:F36) -> 0 | D36: 0 | E36: 0 | F36: 0 | I36: MULTAS | P36: =+C36 -> 0
B37: Gastos bancarios | C37: =SUM(D37:F37) -> 0 | D37: 0 | E37: 0 | F37: 0
B38: Intereses | C38: =SUM(D38:F38) -> 0 | D38: 0 | E38: 0 | F38: 0 | I38: F. FIJOS FORD/VW/PTO 14 | K38: =4800+5000+3000+5000 -> 17800 | L38: 7200 | R38: SON FACTURAS DE COMBUSTIBLE / POR ESO SE SUMA EN COMBUSTIBLES
B39: Combustible | C39: =SUM(D39:F39) -> 1760.8 | D39: 0 | E39: =+SALDOS!C171+SALDOS!C217 -> 1760.8 | F39: 0 | I39: COMBUSTIBLE | J39: 281.16 | K39: =3211.01+4543.6 -> 7754.61 | L39: 1075.53
B40: Comunicaciones | C40: =SUM(D40:F40) -> 1732.02 | D40: 0 | E40: =+SALDOS!C166+SALDOS!D166 -> 1732.02 | F40: 0 | I40: TELEFONOS | J40: =2248.27+2043.98+1241.35 -> 5533.6 | K40: =2543.13+2338.55+2410.41 -> 7292.09 | L40: =1803.75+2112.36+2202.79 -> 6118.9 | M40: 1098.32 | R40: HAY CARGADAS 2 FACTURAS VIEJAS DE NEXTEL QUE NO ESTABAN
B41: Correo | C41: =SUM(D41:F41) -> 0 | D41: 0 | E41: 0 | F41: 0
B42: Custodia | C42: =SUM(D42:F42) -> 0 | D42: =SALDOS!C168 | E42: 0 | F42: 0
...
