Workbook

Sheet SALDOS
A1: TRANSPORTES FURLONG S.A.
A2: del 01/7/2026 al 31/7/2026
B3: Deudor | C3: Acreedor
A5: Activo
A7: 1110100330 FONDO FIJO BS. AS. | B7: =IF(D7>0,D7,0) -> 0 | C7: =IF(D7<0,-D7,0) -> 265310.63 | D7: =IFERROR(VLOOKUP(A7,$A$242:$B$359,2,FALSE),0) -> -265310.63
A8: 1110100340 FONDO FIJO SENASA | B8: =IF(D8>0,D8,0) -> 0 | C8: =IF(D8<0,-D8,0) -> 0 | D8: =IFERROR(VLOOKUP(A8,$A$242:$B$359,2,FALSE),0)
A9: 1110100420 BANCO FRANCES C/C | B9: =IF(D9>0,D9,0) -> 0 | C9: =IF(D9<0,-D9,0) -> 25116050 | D9: =IFERROR(VLOOKUP(A9,$A$242:$B$359,2,FALSE),0) -> -25116050
A10: 1110101050 FONDO FIJO ADELANTOS PDT | B10: =IF(D10>0,D10,0) -> 0 | C10: =IF(D10<0,-D10,0) -> 0 | D10: =IFERROR(VLOOKUP(A10,$A$242:$B$359,2,FALSE),0)
A11: 1120100100 FORD | B11: =IF(D11>0,D11,0) -> 0 | C11: =IF(D11<0,-D11,0) -> 640196.69 | D11: =IFERROR(VLOOKUP(A11,$A$242:$B$359,2,FALSE),0) -> -640196.69
A12: 1120100400 TRANSPORTES FURLONG S.A. AR | B12: =IF(D12>0,D12,0) -> 0 | C12: =IF(D12<0,-D12,0) -> 99288526 | D12: =IFERROR(VLOOKUP(A12,$A$242:$B$359,2,FALSE),0) -> -99288526
A13: 1120100700 RENAULT ARG. S.A. | B13: =IF(D13>0,D13,0) -> 0 | C13: =IF(D13<0,-D13,0) -> 0 | D13: =IFERROR(VLOOKUP(A13,$A$242:$B$359,2,FALSE),0)
A14: 1120101300 VOLKSWAGEN ARGENTINA S.A. | B14: =IF(D14>0,D14,0) -> 304705.08 | C14: =IF(D14<0,-D14,0) -> 0 | D14: =IFERROR(VLOOKUP(A14,$A$242:$B$359,2,FALSE),0) -> 304705.08
A15: 1120101600 FCA AUTOMOBILES ARGENTINA S.A. | B15: =IF(D15>0,D15,0) -> 0 | C15: =IF(D15<0,-D15,0) -> 0 | D15: =IFERROR(VLOOKUP(A15,$A$242:$B$359,2,FALSE),0)
A16: 1120131000 CNH ARGENTINA S.A. | B16: =IF(D16>0,D16,0) -> 0 | C16: =IF(D16<0,-D16,0) -> 108886.7 | D16: =IFERROR(VLOOKUP(A16,$A$242:$B$359,2,FALSE),0) -> -108886.7
A17: 1120138000 STELLANTIS AUTOMOVILES DE ARGENTINA S. A | B17: =IF(D17>0,D17,0) -> 0 | C17: =IF(D17<0,-D17,0) -> 192240.64 | D17: =IFERROR(VLOOKUP(A17,$A$242:$B$359,2,FALSE),0) -> -192240.64
A18: 1140300100 ANTICIPO A PDT | B18: =IF(D18>0,D18,0) -> 4122436.3 | C18: =IF(D18<0,-D18,0) -> 0 | D18: =IFERROR(VLOOKUP(A18,$A$242:$B$359,2,FALSE),0) -> 4122436.3
... A46: 1220500000 AMORT. ACUM. HARDWARE | B46: =IF(D46>0,D46,0) -> 0 | C46: =IF(D46<0,-D46,0) -> 0 | D46: =IFERROR(VLOOKUP(A46,$A$242:$B$359,2,FALSE),0)
A47: 1220700000 AMORT. ACUM. RODADOS | B47: =IF(D47>0,D47,0) -> 0 | C47: =IF(D47<0,-D47,0) -> 2395590 | D47: =IFERROR(VLOOKUP(A47,$A$242:$B$359,2,FALSE),0) -> -2395590 | E47: =SUM(D32:D47) -> -2485298.3
A48: 2.1.1.01.01.0.0 BOSTON CIA ARG DE SEGUROS | B48: =IF(D48>0,D48,0) -> 0 | C48: =IF(D48<0,-D48,0) -> 0 | D48: =IFERROR(VLOOKUP(A48,$A$242:$B$359,2,FALSE),0)
A49: 2.1.1.01.02.0.0 EL COMERCIO CIA DE SEGUROS | B49: =IF(D49>0,D49,0) -> 0 | C49: =IF(D49<0,-D49,0) -> 0 | D49: =IFERROR(VLOOKUP(A49,$A$242:$B$359,2,FALSE),0)
D50: =SUM(D7:D49) -> -1.5141649e+08 | E50: =SUM(B7:B49) -> 6027141.4 | F50: =SUM(C7:C49) -> 1.5744363e+08 | G50: =+E50-F50-D50 -> 0
A51: Pasivo
A53: 2110100300 COTELCAM | B53: =IF(D53>0,D53,0) -> 0 | C53: =IF(D53<0,-D53,0) -> 0 | D53: =IFERROR(VLOOKUP(A53,$A$242:$B$359,2,FALSE),0)
A54: 2110100900 ESTUDIO CORTES | B54: =IF(D54>0,D54,0) -> 0 | C54: =IF(D54<0,-D54,0) -> 0 | D54: =IFERROR(VLOOKUP(A54,$A$242:$B$359,2,FALSE),0)
A55: 2110101500 VENEZIA AUTOS SA | B55: =IF(D55>0,D55,0) -> 0 | C55: =IF(D55<0,-D55,0) -> 0 | D55: =IFERROR(VLOOKUP(A55,$A$242:$B$359,2,FALSE),0)
A56: 2110101800 TRANSPORTES FURLONG ARG. S.A | B56: =IF(D56>0,D56,0) -> 0 | C56: =IF(D56<0,-D56,0) -> 0 | D56: =IFERROR(VLOOKUP(A56,$A$242:$B$359,2,FALSE),0)
A57: 2110102400 OSDE | B57: =IF(D57>0,D57,0) -> 0 | C57: =IF(D57<0,-D57,0) -> 0 | D57: =IFERROR(VLOOKUP(A57,$A$242:$B$359,2,FALSE),0)
A58: 2110105400 MERCOVIA S.A. | B58: =IF(D58>0,D58,0) -> 59338.84 | C58: =IF(D58<0,-D58,0) -> 0 | D58: =IFERROR(VLOOKUP(A58,$A$242:$B$359,2,FALSE),0) -> 59338.84
A59: 2110106800 OKINET SRL | B59: =IF(D59>0,D59,0) -> 162531 | C59: =IF(D59<0,-D59,0) -> 0 | D59: =IFERROR(VLOOKUP(A59,$A$242:$B$359,2,FALSE),0) -> 162531
A60: 2110108900 LA MERIDIONAL S.A. | B60: =IF(D60>0,D60,0) -> 0 | C60: =IF(D60<0,-D60,0) -> 0 | D60: =IFERROR(VLOOKUP(A60,$A$242:$B$359,2,FALSE),0)
A61: 2110115100 GIULI SERGIO ALBERTO | B61: =IF(D61>0,D61,0) -> 0 | C61: =IF(D61<0,-D61,0) -> 0 | D61: =IFERROR(VLOOKUP(A61,$A$242:$B$359,2,FALSE),0)
A62: 2110116700 CARLOS ALEJANDRO DUMA | B62: =IF(D62>0,D62,0) -> 0 | C62: =IF(D62<0,-D62,0) -> 0 | D62: =IFERROR(VLOOKUP(A62,$A$242:$B$359,2,FALSE),0)
A63: 2110118000 MANGGINI PABLO Y ULISES S.H | B63: =IF(D63>0,D63,0) -> 0 | C63: =IF(D63<0,-D63,0) -> 0 | D63: =IFERROR(VLOOKUP(A63,$A$242:$B$359,2,FALSE),0)
A64: 2110120600 QBE SEGUROS LA BUENOS AIRES S.A. | B64: =IF(D64>0,D64,0) -> 22567153 | C64: =IF(D64<0,-D64,0) -> 0 | D64: =IFERROR(VLOOKUP(A64,$A$242:$B$359,2,FALSE),0) -> 22567153
... A109: 2113200000 SERGIO MARCELO MARTIN | B109: =IF(D109>0,D109,0) -> 0 | C109: =IF(D109<0,-D109,0) -> 0 | D109: =IFERROR(VLOOKUP(A109,$A$242:$B$359,2,FALSE),0)
B110: =IF(D110>0,D110,0) -> 0 | C110: =IF(D110<0,-D110,0) -> 0 | D110: =IFERROR(VLOOKUP(A110,$A$242:$B$359,2,FALSE),0)
B111: =IF(D111>0,D111,0) -> 0 | C111: =IF(D111<0,-D111,0) -> 0 | D111: =IFERROR(VLOOKUP(A111,$A$242:$B$359,2,FALSE),0)
A112: 2110805400 HOTEL RENTAL SUITES CAMPANA | B112: =IF(D112>0,D112,0) -> 0 | C112: =IF(D112<0,-D112,0) -> 0 | D112: =IFERROR(VLOOKUP(A112,$A$242:$B$359,2,FALSE),0)
A113: 2116400000 AUTOVIA DEL MERCOSUR | B113: =IF(D113>0,D113,0) -> 0 | C113: =IF(D113<0,-D113,0) -> 0 | D113: =IFERROR(VLOOKUP(A113,$A$242:$B$359,2,FALSE),0)
A114: 2116300000 Sistemas Bejerman | B114: =IF(D114>0,D114,0) -> 48674.67 | C114: =IF(D114<0,-D114,0) -> 0 | D114: =IFERROR(VLOOKUP(A114,$A$242:$B$359,2,FALSE),0) -> 48674.67
...

Sheet EESP
A1: TRANSPORTES FURLONG S.A
A3: 31 de Julio de 2026
A5: Estado de Situación Patrimonial
F9: 46234 | L9: =+F9 -> 46234 | M9: 38717
B10: ACTIVO: | I10: PASIVO
C11: ACTIVO CORRIENTE | I11: PASIVO CORRIENTE
D12: Caja y bancos (Nota 4.a) | F12: =+Activo!F19 -> -25381360 | J12: Deudas
D13: Creditos comerciales | F13: =+Activo!F21 -> 0 | K13: Deudas impositivas | L13: =+Pasivo!E29 -> -32024141
D14: Creditos Impositivos | F14: =+Activo!F37 -> 0 | K14: Deudas accionistas | L14: 0
D15: Inversiones temporarias (Nota 4.b) | F15: =+Activo!F25 -> -20812691 | K15: Comerciales (Nota 4.e) | L15: =+Pasivo!E16 -> 87249492
K16: Otras deudas (Nota 4.f) | L16: 0
D17: Créditos por ventas (Nota 4.c) | F17: =+Activo!F29 -> -636618.95 | K17: Remuneraciones y cs.sociales (Nota 4.f) | L17: =+Pasivo!E30 -> -37946732
K18: Cargas fiscales (Nota 4.h) | L18: =+Pasivo!E37 -> 189282.89
K19: Anticipos de clientes | L19: 0
K20: Dividendos a pagar | L20: 0
K21: Otras deudas (Nota 4.g) | L21: =+Pasivo!E19 -> 0
D22: Otros Creditos (Nota 4.d) | F22: =+Activo!F62 -> -2811999.2 | J22: Total deudas | L22: =+L15+L16+L17+L18 -> 49492043
L23: 0
C24: Total del Activo corriente | F24: =SUM(F12:F22) -> -49642669 | I24: Total del Pasivo Corriente | L24: =+L22 -> 49492043
I25: Total del Pasivo | L25: =+L24 -> 49492043
C28: ACTIVO NO CORRIENTE
D29: Bienes de uso | F29: =+SALDOS!E47 -> -2485298.3 | I29: PATRIMONIO NETO (Según estado respec.) | L29: =+EEPN!I18 -> -1.0162001e+08
C31: Total del Activo no corriente | F31: =SUM(F29:F30) -> -2485298.3 | L31: =+L29 -> -1.0162001e+08
C33: Total del Activo | F33: =+F24+F31 -> -52127967 | I33: Total del Pasivo y Patrimonio Neto | L33: =+L25+L31 -> -52127967

Sheet EERR
A1: TRANSPORTES FURLONG S.A
A3: =+EESP!A3 -> 31 de Julio de 2026
A5: Estado de Resultados
C9: =+EESP!F9 -> 46234 | D9: =+EESP!G9 -> 0
A12: Ingresos por servicios prestados | C12: =+SALDOS!C129-SALDOS!B129 -> 0
A15: Gastos de comercialización (Anexo II) | C15: =+'Anexo II'!E113 -> 94344997
A16: Gastos de administración (Anexo II) | C16: =+'Anexo II'!D113 -> 6217669.7
A17: Gastos de financieros (Anexo II) | C17: =+'Anexo II'!F113 -> 1734653.4
A19: Subtotal | C19: =+C12+C13-C15-C16-C17 -> -1.0229732e+08
A20: Resultado venta bienes de uso | C20: =+SALDOS!C135 -> 0
A21: Recupero de Gastos | C21: =-SALDOS!B132+SALDOS!C132 -> 0
A22: Diferencia de cotización | C22: =-SALDOS!B130+SALDOS!C130 -> 0
A23: Intereses | C23: =+SALDOS!C131+SALDOS!C136 -> 677309.44
A24: Otros ingresos | C24: =+SALDOS!C218
A25: Ganancia antes de impuesto | C25: =+C19+C20+C22+C21+C23+C24 -> -1.0162001e+08
A26: Impuesto a las Ganancias | C26: 0
A28: Ganancia del ejercicio | C28: =+C25-C26 -> -1.0162001e+08

Sheet EEPN
A1: =+EESP!A1 -> TRANSPORTES FURLONG S.A
A2: =+EESP!A3 -> 31 de Julio de 2026 | B2: =+EESP!A3 -> 31 de Julio de 2026
A3: Estado de Evolución del Patrimonio Neto
J5: =+EESP!F9 -> 46234 | K5: =+EESP!G9 -> 0
B6: CONCEPTO | C6: Aportes de los propietarios | F6: Ganancias | G6: Reservadas | I6: Resultados | J6: Total del | K6: Total del
C7: Capital | D7: Ajuste | E7: Total de | F7: Reserva | G7: Otras | H7: Aportes | I7: no | J7: patrimonio | K7: patrimonio
D8: de Capital | E8: Capital | F8: legal | G8: reservas | H8: Irrevocables | I8: asignados | J8: neto | K8: neto
C9: $ | D9: $ | E9: $ | F9: $ | G9: $ | I9: $ | J9: $ | K9: $
B11: Saldos al inicio del ejercicio | C11: 0 | D11: 0 | E11: =+C11+D11 -> 0 | F11: 0 | G11: 0 | H11: 0 | I11: =-SALDOS!D126 -> 0 | J11: =+E11+F11+G11+I11 -> 0
C13: =SUM(C11:C11) -> 0 | D13: =SUM(D11:D11) -> 0 | E13: =SUM(E11:E11) -> 0 | F13: =SUM(F11:F11) -> 0 | G13: =SUM(G11:G11) -> 0 | H13: =SUM(H11:H11) -> 0 | I13: =SUM(I11:I12) -> 0 | J13: =SUM(J11:J12) -> 0 | K13: =SUM(K11:K11) -> 0
B15: Reasignación casa matriz
B16: Ganancia (Pérdida) del ejercicio | I16: =EERR!C28 -> -1.0162001e+08 | J16: =+I16 -> -1.0162001e+08
B18: Total al 31/7/26 | C18: =+C13 -> 0 | D18: =+D13 -> 0 | E18: =+E13 -> 0 | F18: =+F13 -> 0 | G18: =+G13 -> 0 | H18: =+H13 -> 0 | I18: =+I13+I16+I15 -> -1.0162001e+08 | J18: =+J13+J16+J15 -> -1.0162001e+08 | K18: =+K13+K16 -> 0
B19: Total al 31.12.05 | E19: =+C19+D19 -> 0 | G19: 0 | I19: 0 | J19: =+E19 -> 0 | K19: =+G19 -> 0
B21: Las notas y anexos adjuntos forman parte integrante de los estados contables
B22: Informe profesional por separado

Sheet Activo
B1: NOTA 4: | E1: COMPOSICION DE LOS RUBROS
B3: Al 31 de Julio del 2026 - cifras expresadas en Pesos
F6: =+EESP!F9 -> 46234 | H6: 38717
B7: ACTIVO
B8: Activo Corriente
B9: a. | C9: Caja y bancos
D10: - Caja
D11: - Fondo Fijo a rendir
D12: - Fondo Fijo | F12: =-SALDOS!C7+SALDOS!B7 -> -265310.63
D13: - Banco Francés c/c | F13: =-SALDOS!C9+SALDOS!B9 -> -25116050
D14: - Cheques no depositados
D15: - Efectivo casa matriz
D16: - Fondo fijo SENASA | F16: =-SALDOS!C8+SALDOS!B8 -> 0
D17: - Fondo fijo Adelando PDT | F17: =+SALDOS!C10+SALDOS!B10 -> 0
D18: - Valores a depositar
F19: =SUM(F10:F18) -> -25381360
B21: b. | C21: Inversiones temporarias
D22: - Plazo fijo | F22: =-SALDOS!C30 -> 0
D23: - Fondo común de inversión BBVA | F23: =-SALDOS!C29+SALDOS!B29 -> -20812691
D24: - Intereses a dev Plazo Fijo | F24: =+SALDOS!B31 -> 0
F25: =SUM(F22:F24) -> -20812691
B27: c. | C27: Creditos por Ventas
D28: - Deudores por ventas | F28: =+SALDOS!D11+SALDOS!D14+SALDOS!D15+SALDOS!D17+SALDOS!D16 -> -636618.95
F29: =SUM(F28:F28) -> -636618.95
C31: Creditos impositivos
D32: - Retencion de Gcias. | F32: 0
D33: - Retenc. Suss | F33: 0
D34: - Reten. Ingresos Brutos | F34: 0
D35: - Percepcion y Retencion IVA | F35: 0
D36: - Crédito ley 25413 | F36: 0
F37: =SUM(F32:F36) -> 0
B39: d. | C39: Otros créditos
D40: - Transportes Furlong Uruguay
D41: - Transportes Furlong Cordoba
D42: - Adelanto de gastos
D43: - Adelantos Tomás Furlong
D44: - Adelantos PDT | F44: =+SALDOS!B18-SALDOS!C18 -> 4122436.3
D45: - Adelanto honorarios CF
D46: - Adelanto al personal
D47: - Anticipo Combustible Velasco
...

Sheet Pasivo
E1: =+Activo!F6 -> 46234 | G1: 31.03.04 | K1: 31.03.03 | L1: =+EESP!G9 -> 0
A2: Pasivo
A3: Pasivo Corriente
A4: e. | B4: Deudas comerciales
C5: - Provisión Multas a Pagar | E5: 0
C6: - Provisión fletes esporádicos | E6: 0
C7: - Previsiones | E7: 0
C8: - Proveedores | E8: =-SUM(SALDOS!D53:D79)-SALDOS!D88-SALDOS!D101-SALDOS!D114-SALDOS!D115 -> -4089334
C9: - Adelanto casa matriz | E9: =-SALDOS!D95-SALDOS!D12 -> 91338826
C10: - Adelanto de clientes | E10: 0
C11: - Siniestros a pagar | E11: 0
C12: - Prestamos Amx - Claro | E12: 0
C13: - Convenio HSBC | E13: 0
C14: - Rodados a patentar | E14: 0
C15: -Cheques Emitidos | E15: 0
E16: =SUM(E5:E15) -> 87249492
A18: f. | B18: Otras deudas
C19: - Acuerdos CNRT a pagar | E19: 0
C20: - Prestamo Carlos Furlong | E20: 0
C21: - Prestamo Lorena Alves | E21: 0
C22: - Prestamo Cuba | E22: 0
C23: - Prestamo Vera | E23: 0
E24: =SUM(E19:L23) -> 0
A27: f. | B27: Remuneraciones y cs. Sociales
C28: - SUSS a pagar | E28: =+SALDOS!C83-SALDOS!B83 -> -5922590.5
C29: - Sueldos a pagar | E29: =+SALDOS!C82-SALDOS!B82 -> -32024141 | G29: 938.38 | K29: 0
E30: =SUM(E28:E29) -> -37946732 | G30: =SUM(G28:G29) -> 938.38 | K30: =SUM(#REF!) -> #REF!
A32: h. | B32: Cargas Fiscales
C34: - Plan Mis Facilidades | E34: =+SALDOS!C85-SALDOS!B85 -> -83974.39
C35: - Interes a devengar | E35: =+SALDOS!C86-SALDOS!B86 -> 16382.87
C36: - SICORE a pagar | E36: =-SALDOS!B84+SALDOS!C84 -> 256874.41
E37: =SUM(E34:E36) -> 189282.89

Sheet Anexo I
A1: B I E N E S D E U S O
A2: =+EESP!A3 -> 31 de Julio de 2026
B5: VALOR DE ORIGEN | E5: DEPRECIACIONES
B6: VALORES AL | D6: VALORES AL | E6: ACUMULADAS | G6: ALTAS | H6: DEL EJERCICIO | J6: ACUMULADAS | K6: NETO
A7: CONCEPTO | B7: COMIENZO DEL | C7: AUMENTOS | D7: CIERRE DEL | E7: AL INICIO DEL | F7: BAJAS | G7: DEL EJERCICIO | H7: ALICUOTA | I7: MONTO | J7: AL CIERRE DEL | K7: RESULTANTE
B8: EJERCICIO | D8: EJERCICIO | E8: EJERCICIO | J8: EJERCICIO | K8: =+EESP!F9 -> 46234
B9: $ | C9: $ | D9: $ | E9: $ | F9: $ | I9: $ | J9: $ | K9: $
A11: Software | B11: 754089.29 | C11: 0 | D11: =+B11 -> 754089.29 | E11: 754089.29 | H11: 0.2 | I11: =+J11-E11 -> 0 | J11: 754089.29 | K11: =+D11-J11 -> 0
A12: Hardware | B12: 349454.86 | C12: 0 | D12: =+B12 -> 349454.86 | E12: 349454.86 | H12: 0.2 | I12: =+J12-E12 -> 0 | J12: 349454.86 | K12: =+D12-J12 -> 0
A13: Computadoras | B13: 19271906 | C13: 0 | D13: =+B13 -> 19271906 | E13: 16777769 | H13: 0.2 | I13: =+J13-E13 -> 430023.51 | J13: 17207793 | K13: =+D13-J13 -> 2064112.9
A14: Equipos | B14: 2833073.7 | C14: 0 | D14: =+B14 -> 2833073.7 | E14: 2833073.7 | H14: 0.2 | I14: =+J14-E14 -> 0 | J14: 2833073.7 | K14: =+D14-J14 -> 0
A15: Muebles y Utiles | B15: 2913406.5 | C15: 0 | D15: =+B15 -> 2913406.5 | E15: 2735631.6 | H15: 0.1 | I15: =+J15-E15 -> 18518.22 | J15: 2754149.8 | K15: =+D15-J15 -> 159256.65
A16: Instalaciones | B16: 9934406.7 | C16: 0 | D16: =+B16 -> 9934406.7 | E16: 9934406.7 | H16: 0.1 | I16: =+J16-E16 -> 0 | J16: 9934406.7 | K16: =+D16-J16 -> 0
A17: Rodados | B17: 1.6624361e+08 | C17: 0 | D17: =+B17 -> 1.6624361e+08 | E17: 74041451 | F17: 0 | H17: 0.2 | I17: =+J17-E17 -> 11977950 | J17: 86019401 | K17: =+D17-J17 -> 80224213
A18: =+EEPN!B18 -> Total al 31/7/26 | B18: =SUM(B11:B17) -> 2.0229995e+08 | C18: =SUM(C11:C17) -> 0 | D18: =SUM(D11:D17) -> 2.0229995e+08 | E18: =SUM(E11:E17) -> 1.0742588e+08 | F18: =SUM(F17) -> 0 | I18: =+SALDOS!B161 -> 2485298.3 | J18: =SUM(J11:J17) -> 1.1985237e+08 | K18: =SUM(K11:K17) -> 82447582
A21: Las notas y anexos adjuntos forman parte integrante de los estados contables
A22: Informe profesional por separado

Sheet Anexo II
G1: ANEXO II
A3: Información Requerida por el Art. 64 Inc. b) de la Ley 19.550 | F3: Anexo II
A4: =+Activo!B3 -> Al 31 de Julio del 2026 - cifras expresadas en Pesos
C6: TOTALES | D6: GASTOS | E6: GASTOS | F6: GASTOS | G6: TOTALES
B7: CONCEPTOS | C7: AL | D7: DE | E7: DE | G7: AL | J7: GASTOS ADM CTRAL | K7: GASTOS PACHECO | L7: GASTOS CORDOBA | M7: COSTOS TRANSPORTES | N7: TOTAL | O7: PAGOS ANTIC | P7: TRANF CASA MATRIZ | Q7: TOTAL EGRESO
C8: =+EESP!F9 -> 46234 | D8: ADMINISTRACION | E8: COMERCIALIZACION | F8: FINANCIEROS | G8: 31.03.02
B9: Acuerdo Seclo | C9: =SUM(D9:F9) -> 0 | D9: 0 | E9: =+SALDOS!B164 -> 0 | F9: 0
B10: Adelanto Viaje | C10: =SUM(D10:F10) -> 0 | D10: 0 | E10: =+SALDOS!B216 | F10: 0
B11: Alquiler de autos | C11: =SUM(D11:F11) -> 0 | D11: 0 | E11: =+SALDOS!B198 | F11: 0
B12: Alquiler cochera | C12: =SUM(D12:F12) -> 0 | D12: 0 | E12: =+SALDOS!B206 | F12: 0
B13: Alquiler dpto. | C13: =SUM(D13:F13) -> 0 | D13: 0 | E13: =+SALDOS!B204 | F13: 0
B14: Alquiler fotocopiadora | C14: =SUM(D14:F14) -> 467976.4 | D14: =+SALDOS!B163-SALDOS!C163 -> 467976.4 | E14: =+SALDOS!B205 | F14: 0
B15: Alquiler Oficina Móvil | C15: =SUM(D15:F15) -> 0 | D15: =+SALDOS!B167 -> 0 | E15: 0 | F15: 0
B16: Amortizaciones | C16: =SUM(D16:F16) -> 2485298.3 | D16: 0 | E16: =+SALDOS!B161 -> 2485298.3 | F16: 0
B17: Almuerzos | C17: =SUM(D17:F17) -> 0 | D17: 0 | E17: =+SALDOS!B208 | F17: 0
B18: Autónomos Directores | C18: =SUM(D18:F18) -> 72446.22 | D18: =+SALDOS!B160-SALDOS!C160 -> 72446.22 | E18: =+SALDOS!B209 | F18: 0
B19: Agua | C19: =SUM(D19:F19) -> 0 | D19: =+SALDOS!B162 -> 0 | E19: 0 | F19: 0
B20: Ajuste saldo proveedores | C20: =SUM(D20:F20) -> 0 | D20: 0 | E20: 0 | F20: 0
B21: Bs Personales Acc. Y Participacion | C21: =SUM(D21:F21) -> 0 | D21: =++SALDOS!B197 | E21: =+SALDOS!B213 | F21: 0
B22: Sueldos | C22: =SUM(D22:F22) -> 0 | D22: 0 | E22: =+SALDOS!B214 | F22: 0
B23: Cargas Sociales | C23: =SUM(D23:F23) -> 0 | D23: 0 | E23: 0 | F23: 0
B24: Salario Complementario del Decreto 332/20 | C24: =SUM(D24:F24) -> 0 | D24: 0 | E24: =-SALDOS!C165 -> 0 | F24: 0
B25: Cesión de Derechos | C25: =SUM(D25:F25) -> 0 | D25: =+SALDOS!B217 | E25: 0 | F25: 0
B26: Comisiones | C26: =SUM(D26:F26) -> 0 | D26: 0 | E26: 0 | F26: 0
B27: Gastos varios clientes | C27: =SUM(D27:F27) -> 0 | D27: 0 | E27: =+SALDOS!B220 | F27: 0
B28: Verificación Técnica Vehicular | C28: =SUM(D28:F28) -> 80711 | D28: 0 | E28: =+SALDOS!B215 -> 80711 | F28: 0
B29: Amortizaciones | C29: =SUM(D29:F29) -> 0 | D29: 0 | E29: 0 | F29: 0
B30: Accidentes | C30: =SUM(D30:F30) -> 0 | D30: 0 | E30: =+SALDOS!B199 | F30: 0 | I30: OBRA SOCIAL | J30: 3400.5126 | K30: 5282.0813 | L30: 3714.6061 | P30: 4372 | R30: ACA ES LA FACTURA QUE SE VA A PAGAR EL MES PRÓXIMO SE INCLUYE EN CARGAS SOCIALES (EN EL BALANCE)
B31: Cargas Sociales | C31: =SUM(D31:F31) -> 8933342.3 | D31: 0 | E31: =+SALDOS!B143+SALDOS!B145 -> 8933342.3 | F31: 0 | I31: C SOCIALES | J31: 7385.6622 | K31: 30178.815 | L31: 9981.5423 | R31: CORRESPONDE AL MES DE MAYO / SE PAGA EN JUNIO
B32: Telefonos | C32: =SUM(D32:F32) -> 0 | D32: 0 | E32: 0 | F32: 0
B33: Librería | C33: =SUM(D33:F33) -> 0 | D33: =+SALDOS!B141 -> 0 | E33: 0 | F33: 0
B34: Leasing | C34: =SUM(D34:F34) -> 0 | D34: 0 | E34: =+SALDOS!B226 | F34: 0 | I34: ALQUILER | L34: =+E34 -> 0
B35: Viaticos | C35: =SUM(D35:F35) -> 0 | D35: 0 | E35: 0 | F35: 0
B36: Repuestos y reparaciones | C36: =SUM(D36:F36) -> 0 | D36: 0 | E36: 0 | F36: 0
B37: Catering | C37: =SUM(D37:F37) -> 0 | D37: =+SALDOS!B155 -> 0 | E37: 0 | F37: 0 | I37: COMIDA | J37: 474 | K37: 528
B38: CNRT | C38: =SUM(D38:F38) -> 0 | D38: 0 | E38: =+SALDOS!B187 | F38: 0 | I38: MULTAS | P38: =+C38 -> 0
B39: Gastos bancarios | C39: =SUM(D39:F39) -> 0 | D39: 0 | E39: 0 | F39: 0
B40: Intereses | C40: =SUM(D40:F40) -> 0 | D40: 0 | E40: 0 | F40: 0 | I40: F. FIJOS FORD/VW/PTO 14 | K40: =4800+5000+3000+5000 -> 17800 | L40: 7200 | R40: SON FACTURAS DE COMBUSTIBLE / POR ESO SE SUMA EN COMBUSTIBLES
B41: Combustible | C41: =SUM(D41:F41) -> 506825.21 | D41: 0 | E41: =+SALDOS!B182+SALDOS!B230 -> 506825.21 | F41: 0 | I41: COMBUSTIBLE | J41: 281.16 | K41: =3211.01+4543.6 -> 7754.61 | L41: 1075.53
B42: Comunicaciones | C42: =SUM(D42:F42) -> 505527.94 | D42: 0 | E42: =-SALDOS!C176+SALDOS!B176 -> 505527.94 | F42: 0 | I42: TELEFONOS | J42: =2248.27+2043.98+1241.35 -> 5533.6 | K42: =2543.13+2338.55+2410.41 -> 7292.09 | L42: =1803.75+2112.36+2202.79 -> 6118.9 | M42: 1098.32 | R42: HAY CARGADAS 2 FACTURAS VIEJAS DE NEXTEL QUE NO ESTABAN
...
